<?xml version="1.0" encoding="utf-8"?>
<!-- This URDF was automatically created by SolidWorks to URDF Exporter! Originally created by Stephen Brawner (brawner@gmail.com) 
     Commit Version: 1.6.0-1-g15f4949  Build Version: 1.6.7594.29634
     For more information, please see http://wiki.ros.org/sw_urdf_exporter -->
<robot
  name="mz04_description">
  <link
    name="mz04_link0">
    <inertial>
      <origin
        xyz="-0.0447592951687411 -3.12023369808615E-05 0.0857515328613791"
        rpy="0 0 0" />
      <mass
        value="3.51300927353187" />
      <inertia
        ixx="0.0123702735738967"
        ixy="4.88931962536981E-06"
        ixz="-0.000132246706714302"
        iyy="0.0155845913287364"
        iyz="-1.71455277676881E-05"
        izz="0.0134618664075027" />
    </inertial>
    <visual>
      <origin
        xyz="0 0 0"
        rpy="0 0 0" />
      <geometry>
        <mesh
          filename="package://mz04_description/meshes/mz04_link0.STL" />
      </geometry>
      <material
        name="">
        <color
          rgba="0.250980392156863 0.250980392156863 0.250980392156863 1" />
      </material>
    </visual>
    <collision>
      <origin
        xyz="0 0 0"
        rpy="0 0 0" />
      <geometry>
        <mesh
          filename="package://mz04_description/meshes/mz04_link0.STL" />
      </geometry>
    </collision>
  </link>
  <link
    name="mz04_link1">
    <inertial>
      <origin
        xyz="-0.0197023514199581 0.000938298692799631 0.0855256712156905"
        rpy="0 0 0" />
      <mass
        value="3.29244591173868" />
      <inertia
        ixx="0.0222350895636315"
        ixy="-6.0973596097687E-05"
        ixz="-0.00175393698078112"
        iyy="0.0154200096606875"
        iyz="-0.000258002191557829"
        izz="0.0150764764826899" />
    </inertial>
    <visual>
      <origin
        xyz="0 0 0"
        rpy="0 0 0" />
      <geometry>
        <mesh
          filename="package://mz04_description/meshes/mz04_link1.STL" />
      </geometry>
      <material
        name="">
        <color
          rgba="1 1 1 1" />
      </material>
    </visual>
    <collision>
      <origin
        xyz="0 0 0"
        rpy="0 0 0" />
      <geometry>
        <mesh
          filename="package://mz04_description/meshes/mz04_link1.STL" />
      </geometry>
    </collision>
  </link>
  <joint
    name="mz04_joint1"
    type="revolute">
    <origin
      xyz="0 0 0.171"
      rpy="0 0 0" />
    <parent
      link="mz04_link0" />
    <child
      link="mz04_link1" />
    <axis
      xyz="0 0 -1" />
    <limit
      lower="-2.97"
      upper="2.97"
      effort="10"
      velocity="8.38" />
  </joint>
  <link
    name="mz04_link2">
    <inertial>
      <origin
        xyz="-0.0229430342959031 -0.129313116426115 -0.000857512097067098"
        rpy="0 0 0" />
      <mass
        value="3.43354405526974" />
      <inertia
        ixx="0.0374859154128489"
        ixy="-0.000577795026903937"
        ixz="6.67389962661599E-05"
        iyy="0.0140465634657448"
        iyz="0.000377486259040234"
        izz="0.0301480758700004" />
    </inertial>
    <visual>
      <origin
        xyz="0 0 0"
        rpy="0 0 0" />
      <geometry>
        <mesh
          filename="package://mz04_description/meshes/mz04_link2.STL" />
      </geometry>
      <material
        name="">
        <color
          rgba="1 1 1 1" />
      </material>
    </visual>
    <collision>
      <origin
        xyz="0 0 0"
        rpy="0 0 0" />
      <geometry>
        <mesh
          filename="package://mz04_description/meshes/mz04_link2.STL" />
      </geometry>
    </collision>
  </link>
  <joint
    name="mz04_joint2"
    type="revolute">
    <origin
      xyz="0 0 0.169"
      rpy="-1.5708 0 0" />
    <parent
      link="mz04_link1" />
    <child
      link="mz04_link2" />
    <axis
      xyz="0 0 1" />
    <limit
      lower="-2.53"
      upper="1.57"
      effort="10"
      velocity="8.03" />
  </joint>
  <link
    name="mz04_link3">
    <inertial>
      <origin
        xyz="0.00557516997606589 -0.000280097155568842 -0.000264708631542377"
        rpy="0 0 0" />
      <mass
        value="1.75772574412506" />
      <inertia
        ixx="0.0032167713214568"
        ixy="-0.000191167581086016"
        ixz="1.23933539489604E-06"
        iyy="0.00322653422939074"
        iyz="5.25316745371768E-06"
        izz="0.00390619750681237" />
    </inertial>
    <visual>
      <origin
        xyz="0 0 0"
        rpy="0 0 0" />
      <geometry>
        <mesh
          filename="package://mz04_description/meshes/mz04_link3.STL" />
      </geometry>
      <material
        name="">
        <color
          rgba="1 1 1 1" />
      </material>
    </visual>
    <collision>
      <origin
        xyz="0 0 0"
        rpy="0 0 0" />
      <geometry>
        <mesh
          filename="package://mz04_description/meshes/mz04_link3.STL" />
      </geometry>
    </collision>
  </link>
  <joint
    name="mz04_joint3"
    type="revolute">
    <origin
      xyz="0 -0.26 0"
      rpy="0 0 -1.5708" />
    <parent
      link="mz04_link2" />
    <child
      link="mz04_link3" />
    <axis
      xyz="0 0 1" />
    <limit
      lower="-2.18"
      upper="4.89"
      effort="10"
      velocity="9.08" />
  </joint>
  <link
    name="mz04_link4">
    <inertial>
      <origin
        xyz="0.00309024473150554 -0.000145366515908234 -0.102946189818116"
        rpy="0 0 0" />
      <mass
        value="1.70562401190118" />
      <inertia
        ixx="0.00721639807702088"
        ixy="-3.42236031590701E-07"
        ixz="5.92374124737924E-05"
        iyy="0.00686286874449402"
        iyz="5.84968158425155E-06"
        izz="0.00220615434229459" />
    </inertial>
    <visual>
      <origin
        xyz="0 0 0"
        rpy="0 0 0" />
      <geometry>
        <mesh
          filename="package://mz04_description/meshes/mz04_link4.STL" />
      </geometry>
      <material
        name="">
        <color
          rgba="1 1 1 1" />
      </material>
    </visual>
    <collision>
      <origin
        xyz="0 0 0"
        rpy="0 0 0" />
      <geometry>
        <mesh
          filename="package://mz04_description/meshes/mz04_link4.STL" />
      </geometry>
    </collision>
  </link>
  <joint
    name="mz04_joint4"
    type="revolute">
    <origin
      xyz="0.0249999999999999 0.28 0"
      rpy="-1.5707963267949 0 0" />
    <parent
      link="mz04_link3" />
    <child
      link="mz04_link4" />
    <axis
      xyz="0 0 -1" />
    <limit
      lower="-3.32"
      upper="3.32"
      effort="10"
      velocity="9.77" />
  </joint>
  <link
    name="mz04_link5">
    <inertial>
      <origin
        xyz="-5.86547276966165E-05 0.0199090373472192 -0.00293631213635448"
        rpy="0 0 0" />
      <mass
        value="0.336399836903676" />
      <inertia
        ixx="0.000446624368283086"
        ixy="2.47061371480887E-07"
        ixz="6.15821325897774E-07"
        iyy="0.000330568174441235"
        iyz="-1.87705108529991E-05"
        izz="0.000351036334434016" />
    </inertial>
    <visual>
      <origin
        xyz="0 0 0"
        rpy="0 0 0" />
      <geometry>
        <mesh
          filename="package://mz04_description/meshes/mz04_link5.STL" />
      </geometry>
      <material
        name="">
        <color
          rgba="1 1 1 1" />
      </material>
    </visual>
    <collision>
      <origin
        xyz="0 0 0"
        rpy="0 0 0" />
      <geometry>
        <mesh
          filename="package://mz04_description/meshes/mz04_link5.STL" />
      </geometry>
    </collision>
  </link>
  <joint
    name="mz04_joint5"
    type="revolute">
    <origin
      xyz="0 0 0"
      rpy="1.5707963267949 0 0" />
    <parent
      link="mz04_link4" />
    <child
      link="mz04_link5" />
    <axis
      xyz="0 0 1" />
    <limit
      lower="-2.09"
      upper="2.09"
      effort="9.77"
      velocity="9.77" />
  </joint>
  <link
    name="mz04_link6">
    <inertial>
      <origin
        xyz="0.00020870301755449 5.54207254168023E-05 0.0685507759319275"
        rpy="0 0 0" />
      <mass
        value="0.0340082287388899" />
      <inertia
        ixx="8.72489057883343E-06"
        ixy="5.14603740499548E-08"
        ixz="-7.72265367887762E-09"
        iyy="8.58258061822553E-06"
        iyz="-2.01661845696461E-09"
        izz="1.61785714739617E-05" />
    </inertial>
    <visual>
      <origin
        xyz="0 0 0"
        rpy="0 0 0" />
      <geometry>
        <mesh
          filename="package://mz04_description/meshes/mz04_link6.STL" />
      </geometry>
      <material
        name="">
        <color
          rgba="0.250980392156863 0.250980392156863 0.250980392156863 1" />
      </material>
    </visual>
    <collision>
      <origin
        xyz="0 0 0"
        rpy="0 0 0" />
      <geometry>
        <mesh
          filename="package://mz04_description/meshes/mz04_link6.STL" />
      </geometry>
    </collision>
  </link>
  <joint
    name="mz04_joint6"
    type="revolute">
    <origin
      xyz="0 0 0"
      rpy="-1.5707963267949 0 0" />
    <parent
      link="mz04_link5" />
    <child
      link="mz04_link6" />
    <axis
      xyz="0 0 -1" />
    <limit
      lower="-3.14"
      upper="3.14"
      effort="10"
      velocity="15.71" />
  </joint>
</robot>