<?xml version="1.0" encoding="utf-8"?>
<!-- =================================================================================== -->
<!-- |    This document was autogenerated by xacro from dual_mz04_right_arm.urdf.xacro | -->
<!-- |    EDITING THIS FILE BY HAND IS NOT RECOMMENDED                                 | -->
<!-- =================================================================================== -->
<robot name="right_arm">
  <!-- for simulation -->
  <!--    <link name="world" />-->
  <!--    <joint name="robot_to_world" type="fixed">-->
  <!--      <parent link="world" />-->
  <!--      <child link="${arm_id}_link0" />-->
  <!--      <origin xyz="0.0 0.0 0.0" rpy="0.0 0.0 0.0" />-->
  <!--    </joint>-->
  <!-- end for simulation -->
  <link name="arm_R_link0">
    <visual>
      <geometry>
        <mesh filename="package://mz04_description/meshes/visual/link0.dae"/>
      </geometry>
    </visual>
    <collision>
      <geometry>
        <mesh filename="package://mz04_description/meshes/collision/link0.stl"/>
      </geometry>
    </collision>
  </link>
  <link name="arm_R_link1">
    <visual>
      <geometry>
        <mesh filename="package://mz04_description/meshes/visual/link1.dae"/>
      </geometry>
    </visual>
    <collision>
      <geometry>
        <mesh filename="package://mz04_description/meshes/collision/link1.stl"/>
      </geometry>
    </collision>
    <!-- for simulation -->
    <inertial>
      <origin rpy="0 0 0" xyz="-0.0197023514199581 0.000938298692799631 0.0855256712156905"/>
      <mass value="3.29244591173868"/>
      <inertia ixx="0.0222350895636315" ixy="-6.0973596097687E-05" ixz="-0.00175393698078112" iyy="0.0154200096606875" iyz="-0.000258002191557829" izz="0.0150764764826899"/>
    </inertial>
    <!-- end for simulation -->
  </link>
  <joint name="arm_R_joint1" type="revolute">
    <safety_controller k_position="100.0" k_velocity="40.0" soft_lower_limit="-2.97" soft_upper_limit="2.97"/>
    <origin rpy="0 0 0" xyz="0 0 0.171"/>
    <parent link="arm_R_link0"/>
    <child link="arm_R_link1"/>
    <axis xyz="0 0 1"/>
    <limit effort="100" lower="-2.97" upper="2.97" velocity="8.38"/>
    <!-- for simulation -->
    <dynamics damping="1.0"/>
    <!-- end for simulation -->
  </joint>
  <link name="arm_R_link2">
    <visual>
      <geometry>
        <mesh filename="package://mz04_description/meshes/visual/link2.dae"/>
      </geometry>
    </visual>
    <collision>
      <geometry>
        <mesh filename="package://mz04_description/meshes/collision/link2.stl"/>
      </geometry>
    </collision>
    <!-- for simulation -->
    <inertial>
      <origin rpy="0 0 0" xyz="-0.0229430342959031 -0.129313116426115 -0.000857512097067098"/>
      <mass value="3.43354405526974"/>
      <inertia ixx="0.0374859154128489" ixy="-0.000577795026903937" ixz="6.67389962661599E-05" iyy="0.0140465634657448" iyz="0.000377486259040234" izz="0.0301480758700004"/>
    </inertial>
    <!-- end for simulation -->
  </link>
  <joint name="arm_R_joint2" type="revolute">
    <safety_controller k_position="100.0" k_velocity="40.0" soft_lower_limit="-2.53" soft_upper_limit="1.57"/>
    <origin rpy="-1.57079632679 0 0" xyz="0 0 0.169"/>
    <parent link="arm_R_link1"/>
    <child link="arm_R_link2"/>
    <axis xyz="0 0 -1"/>
    <limit effort="100" lower="-2.53" upper="1.57" velocity="8.03"/>
    <!-- for simulation -->
    <dynamics damping="1.0"/>
    <!-- end for simulation -->
  </joint>
  <link name="arm_R_link3">
    <visual>
      <geometry>
        <mesh filename="package://mz04_description/meshes/visual/link3.dae"/>
      </geometry>
    </visual>
    <collision>
      <geometry>
        <mesh filename="package://mz04_description/meshes/collision/link3.stl"/>
      </geometry>
    </collision>
    <!-- for simulation -->
    <inertial>
      <origin rpy="0 0 0" xyz="0.00557516997606589 -0.000280097155568842 -0.000264708631542377"/>
      <mass value="1.75772574412506"/>
      <inertia ixx="0.0032167713214568" ixy="-0.000191167581086016" ixz="1.23933539489604E-06" iyy="0.00322653422939074" iyz="5.25316745371768E-06" izz="0.00390619750681237"/>
    </inertial>
    <!-- end for simulation -->
  </link>
  <joint name="arm_R_joint3" type="revolute">
    <safety_controller k_position="100.0" k_velocity="40.0" soft_lower_limit="-2.18" soft_upper_limit="4.89"/>
    <origin rpy="0 0 -1.57079632679" xyz="0 -0.26 0"/>
    <parent link="arm_R_link2"/>
    <child link="arm_R_link3"/>
    <axis xyz="0 0 -1"/>
    <limit effort="100" lower="-2.18" upper="4.89" velocity="9.08"/>
    <!-- for simulation -->
    <dynamics damping="1.0"/>
    <!-- end for simulation -->
  </joint>
  <link name="arm_R_link4">
    <visual>
      <geometry>
        <mesh filename="package://mz04_description/meshes/visual/link4.dae"/>
      </geometry>
    </visual>
    <collision>
      <geometry>
        <mesh filename="package://mz04_description/meshes/collision/link4.stl"/>
      </geometry>
    </collision>
    <!-- for simulation -->
    <inertial>
      <origin rpy="0 0 0" xyz="0.00309024473150554 -0.000145366515908234 -0.102946189818116"/>
      <mass value="1.70562401190118"/>
      <inertia ixx="0.00721639807702088" ixy="-3.42236031590701E-07" ixz="5.92374124737924E-05" iyy="0.00686286874449402" iyz="5.84968158425155E-06" izz="0.00220615434229459"/>
    </inertial>
    <!-- end for simulation -->
  </link>
  <joint name="arm_R_joint4" type="revolute">
    <safety_controller k_position="100.0" k_velocity="40.0" soft_lower_limit="-3.32" soft_upper_limit="3.32"/>
    <origin rpy="-1.57079632679 0 0" xyz="0.0249999999999999 0.28 0"/>
    <parent link="arm_R_link3"/>
    <child link="arm_R_link4"/>
    <axis xyz="0 0 1"/>
    <limit effort="100" lower="-3.32" upper="3.32" velocity="9.77"/>
    <!-- for simulation -->
    <dynamics damping="1.0"/>
    <!-- end for simulation -->
  </joint>
  <link name="arm_R_link5">
    <visual>
      <geometry>
        <mesh filename="package://mz04_description/meshes/visual/link5.dae"/>
      </geometry>
    </visual>
    <collision>
      <geometry>
        <mesh filename="package://mz04_description/meshes/collision/link5.stl"/>
      </geometry>
    </collision>
    <!-- for simulation -->
    <inertial>
      <origin rpy="0 0 0" xyz="-5.86547276966165E-05 0.0199090373472192 -0.00293631213635448"/>
      <mass value="0.336399836903676"/>
      <inertia ixx="0.000446624368283086" ixy="2.47061371480887E-07" ixz="6.15821325897774E-07" iyy="0.000330568174441235" iyz="-1.87705108529991E-05" izz="0.000351036334434016"/>
    </inertial>
    <!-- end for simulation -->
  </link>
  <joint name="arm_R_joint5" type="revolute">
    <safety_controller k_position="100.0" k_velocity="40.0" soft_lower_limit="-2.09" soft_upper_limit="2.09"/>
    <origin rpy="1.57079632679 0 0" xyz="0 0 0"/>
    <parent link="arm_R_link4"/>
    <child link="arm_R_link5"/>
    <axis xyz="0 0 -1"/>
    <limit effort="100" lower="-2.09" upper="2.09" velocity="9.77"/>
    <!-- for simulation -->
    <dynamics damping="1.0"/>
    <!-- end for simulation -->
  </joint>
  <link name="arm_R_link6">
    <visual>
      <geometry>
        <mesh filename="package://mz04_description/meshes/visual/link6.dae"/>
      </geometry>
    </visual>
    <collision>
      <geometry>
        <mesh filename="package://mz04_description/meshes/collision/link6.stl"/>
      </geometry>
    </collision>
    <!-- for simulation -->
    <inertial>
      <origin rpy="0 0 0" xyz="0.00020870301755449 5.54207254168023E-05 0.0685507759319275"/>
      <mass value="0.0340082287388899"/>
      <inertia ixx="8.72489057883343E-06" ixy="5.14603740499548E-08" ixz="-7.72265367887762E-09" iyy="8.58258061822553E-06" iyz="-2.01661845696461E-09" izz="1.61785714739617E-05"/>
    </inertial>
    <!-- end for simulation -->
  </link>
  <joint name="arm_R_joint6" type="revolute">
    <safety_controller k_position="100.0" k_velocity="40.0" soft_lower_limit="-6.28" soft_upper_limit="6.28"/>
    <origin rpy="-1.57079632679 0 0" xyz="0 0.072 0"/>
    <parent link="arm_R_link5"/>
    <child link="arm_R_link6"/>
    <axis xyz="0 0 1"/>
    <limit effort="10" lower="-6.28" upper="6.28" velocity="15.71"/>
    <!-- for simulation -->
    <dynamics damping="1.0"/>
    <!-- end for simulation -->
  </joint>
</robot>
